import { throwError, throwCustomError, resolveValue, MyAwesomeError, rejectCustomError } from './index';

describe('resolveValue', () => {
  test('should resolve provided value', async () => {
    const value = 42;
    const result = await resolveValue(value);
    expect(result).toBe(value);
  });
});

describe('throwError', () => {
  test('should throw error with provided message', () => {
    const errorMessage = 'Test error message';
    expect(() => throwError(errorMessage)).toThrow(errorMessage);
  });

  test('should throw error with default message if message is not provided', () => {
    expect(() => throwError()).toThrow('Oops!');
  });
});

describe('throwCustomError', () => {
  test('should throw custom error', () => {
    expect(() => throwCustomError()).toThrow(MyAwesomeError);
  });
});

describe('rejectCustomError', () => {
  test('should reject custom error', async () => {
    await expect(rejectCustomError()).rejects.toThrow(MyAwesomeError);
  });
});
